Workbook

Sheet Dataset
A1: ID | B1: Date | C1: Year | D1: Victim Platform | E1: Loss (as reported) | F1: Gross Bridge-Specific Loss (USD) | G1: Loss Normalization Note | H1: Attack Pattern & Root Cause | I1: Source 1 | J1: Source 2 | K1: Source 3 | L1: Evidence Level | M1: Attack Pattern | N1: Primary Functional Domain | O1: Reason (Why This Pattern & Domain) | P1: Scope / Evidence Note | Q1: Enabling Mechanism | R1: Boundary Case | S1: Alternative Pattern | T1: Alternative Domain | U1: Classification Confidence | V1: Coder 2 – Attack Pattern | W1: Coder 2 – Primary Functional Domain | X1: Loss Basis
A2: BR-001 | B2: 46257 | C2: =YEAR(B2) -> 2026 | D2: warp.green ERC-20 Bridge (Chia ↔ Ethereum/Base) | E2: ~$93K | F2: 93000 | H2: A Chia-side Chialisp puzzle bug in the ERC-20 bridge module (the separate CAT bridge, securing assets like wXCH, was unaffected). The attacker minted worthless CAT tokens on Chia and presented them to the trusted validator set as legitimately burned wUSDC. Validators signed off on the fake burn attestations, authorizing the EVM side to release real USDC — draining ~85,000 wUSDC.b and 8,000 wUSDC (~$93K) from the Ethereum/Base bridge contracts, later converted to ETH and moved through Tornado Cash. The team offered the attacker a 10% white-hat bounty for returning 90% of funds within 48 hours; the attacker declined. | I2: https://www.gate.com/news/detail/warpgreen-confirms-erc-20-bridge-vulnerability-offers-attacker-10-white-hat-23695179 | J2: https://hacked.slowmist.io/?c=Bridge | K2: https://xch.today/2026/08/26/a-difficult-week-for-chia-defi-warp-green-tibetswap-and-circuit/ | L2: E2 | M2: Event Injection (EI) | N2: FD-1 Deposit | O2: The attacker fabricated a fake burn signal, a worthless minted token presented as a real burn, and the validator set accepted that fabricated signal as proof of a genuine action without independently confirming it. This is the core Event Injection behavior, a crafted signal accepted as a real bridge event, and for this we have mapped it to Event Injection (EI). A burn is the bridge's mirror image of a deposit, and the forged signal is what fooled that exact deposit-recognition point, so for this we have mapped it to FD-1 Deposit. | Q2: None recorded | R2: No | U2: =IF(L2="E4","Low",IF(OR(R2="Yes",L2="E3"),"Medium","High")) -> High | X2: Bridge-held assets withdrawn
A3: BR-002 | B3: 46255 | C3: =YEAR(B3) -> 2026 | D3: The Sandbox Bridge (SAND / LayerZero OFT — Base & BNB Chain) | E3: ~$1.5M economic impact (~$697K direct vault drain) | F3: 697000 | G3: Reported as Aug 21–22, 2026; start date used.; Direct vault drain only; ~$1.5M "economic impact" (incl. token price effects) excluded. | H3: A configuration flaw, not a LayerZero protocol bug (confirmed by Blockaid). SAND's omnichain fungible token (OFT) contract on Base and BNB Chain exposed an approveAndCall function that let the attacker submit a crafted payload causing the contract to call setDelegate on itself, making the attacker the sole verifier of incoming LayerZero bridge messages for that contract. With that control, the attacker forged bridge messages authorizing mints with no corresponding real burn/lock on Ethereum, minting 50M+ SAND initially and eventually over 339 trillion unbacked SAND across Base/BNB Chain, and redeeming 14,742,341.84 real SAND (~$697K) from the Ethereum vault before the team cut LayerZero peer trust and permanently retired the compromised contracts. Ethereum and Polygon SAND were unaffected. | I3: https://www.sandbox.game/en/blog/august-22-exploit-post-mortem/ | J3: https://crypto.news/sandbox-329-trillion-sand-bridge-exploit-675k-stolen/ | K3: https://cointelegraph.com/news/the-sandbox-compensation-sand-bridge-exploit | L3: E1 | M3: Proof Forgery (PF) | N3: FD-3 Verification | O3: The attacker seized control of the message verification role itself via setDelegate, then used that control to forge bridge messages authorizing mints with no real burn or lock behind them. Forging a message that bypasses the verification gate to release funds without a genuine deposit is the defining behavior of Proof Forgery, and for this we have mapped it to Proof Forgery (PF). The compromised component was specifically who is trusted to verify incoming LayerZero messages, so for this we have mapped it to FD-3 Verification. | Q3: None recorded | R3: No | U3: =IF(L3="E4","Low",IF(OR(R3="Yes",L3="E3"),"Medium","High")) -> High | X3: Bridge-held assets withdrawn
A4: BR-003 | B4: 46253 | C4: =YEAR(B4) -> 2026 | D4: Allbridge (Base CCTP router) | E4: ~$190K | F4: 190000 | H4: Allbridge's new Base router integrated Circle's CCTP, but its receiveCctpMessage handler credited the amount written inside an attested Circle message as a spendable deposit without verifying that USDC had actually been minted/delivered to the bridge. The attacker pre-staged a forged message on Polygon 24 days earlier (Circle's MessageTransmitterV2.sendMessage will attest any payload shaped like a deposit, with no burn/mint attached), then — six seconds after a real, unrelated deposit landed and topped up the router's balance — redeemed the forged message, flash-loaned the remaining shortfall (~$809K) from Aave, and withdrew ~$999K, netting ~$190K after repaying the loan. | I4: https://slowmist.medium.com/a-cross-chain-attack-spanning-one-month-analysis-of-the-allbridge-hack-32a6183bce08 | J4: https://defimon.xyz/blog/allbridge-hack-august-2026 | K4: https://broadchain.info/en/articles/tpeh93 | L4: E2 | M4: Event Injection (EI) | N4: FD-1 Deposit | O4: receiveCctpMessage treated the mere existence of an attested message as proof of a deposit, without checking that the funds it described had actually been minted or delivered. Accepting a fake deposit signal as real, with no genuine funds behind it, is the Event Injection pattern, and for this we have mapped it to Event Injection (EI). The vulnerable check is exactly the one meant to confirm a genuine deposit occurred before crediting a balance, so for this we have mapped it to FD-1 Deposit. | Q4: Flash loan | R4: Yes | S4: Proof Forgery (PF) | T4: FD-3 Verification | U4: =IF(L4="E4","Low",IF(OR(R4="Yes",L4="E3"),"Medium","High")) -> Medium | X4: Bridge-held assets withdrawn
A5: BR-004 | B5: 46243 | C5: =YEAR(B5) -> 2026 | D5: Coreum/tx XRP Ledger Bridge | E5: $200K | F5: 200000 | H5: The bridge's relayer software watched the bridge account's transaction history for payments carrying a "Coreum recipient" memo and treated a matching memo as proof of deposit — without ever checking that the payment's destination was actually the bridge address. Since the bridge itself issues the wrapped Coreum token on the XRP Ledger, the attacker simply moved that wrapped token between two wallets they controlled, attached a fake deposit memo, and the transaction showed up in the bridge account's own history. 21 relayers attested the phantom deposit; a 17-of-28 multisig quorum then co-signed 94 real XRP withdrawals over 97 minutes, draining 99.7% of the bridge's XRP reserve. All relayers ran the same unpatched code, so "independent" signers reached identical (wrong) conclusions. | I5: https://en.cryptonomist.ch/2026/08/12/xrp-coreum-bridge-hack/ | J5: https://sigintzero.com/blog/coreum-bridge-200k-xrp-rippling-deposit-forgery | K5: https://shattered.io/coreum-bridge-hack-200k-xrp-2026/ | L5: E2 | M5: Event Injection (EI) | N5: FD-1 Deposit | O5: Relayers accepted a self-sent transfer carrying a fake deposit memo as proof of a real deposit, without checking the transaction actually went to the bridge address. A fabricated deposit signal accepted at face value is the Event Injection pattern, and for this we have mapped it to Event Injection (EI). The flaw is in how a deposit is recognized and attested in the first place, so for this we have mapped it to FD-1 Deposit. | Q5: None recorded | R5: No | U5: =IF(L5="E4","Low",IF(OR(R5="Yes",L5="E3"),"Medium","High")) -> High | X5: Bridge-held assets withdrawn
A6: BR-005 | B6: 46226 | C6: =YEAR(B6) -> 2026 | D6: Verus-Ethereum Bridge (2nd incident, repeat attack) | E6: ~$7.54M | F6: 7540000 | H6: The same vulnerability class as the May 18, 2026 Verus-Ethereum Bridge incident (see that record), reused against the same contract and entry path (submitImports) just two weeks after recovered funds from the May attack had been redeposited into the bridge — strongly suggesting the original fix was incomplete or the patch was never fully deployed. A different attacker, using a new wallet, drained ETH, tBTC, USDC, USDT, EURC, MKR, and scrvUSD. | I6: https://www.certik.com/blog/verus-incident-analysis | J6: https://sigintzero.com/blog/verus-bridge-7-5m-state-root-parser-divergence | K6: https://www.cryptotimes.io/2026/07/26/crypto-loses-over-47m-in-a-week-as-afx-trade-wanchain-verus-get-hacked/ | L6: E2 | M6: Proof Forgery (PF) | N6: FD-3 Verification | O6: submitImports confirmed a transfer hash existed but never checked that the value was actually backed by locked collateral on Verus, so the verification step accepted an unbacked claim as valid. Bypassing the verification check to release funds with no genuine backing is Proof Forgery, and for this we have mapped it to Proof Forgery (PF). The flaw lives in the bridge's cross-chain transfer verification function, so for this we have mapped it to FD-3 Verification. | Q6: None recorded | R6: No | U6: =IF(L6="E4","Low",IF(OR(R6="Yes",L6="E3"),"Medium","High")) -> High | X6: Bridge-held assets withdrawn
A7: BR-006 | B7: 46225 | C7: =YEAR(B7) -> 2026 | D7: AFX Trade (Arbitrum custodial bridge) | E7: ~$24.15M | F7: 24150000 | H7: A validator private-key compromise, similar in kind to IoTeX. The attacker obtained private keys belonging to five of AFX's bridge validators — enough to reach the quorum threshold required to approve a withdrawal. The bridge contract did have a 200-second challenge period meant to let anyone flag a suspicious pending withdrawal, but nobody filed a challenge in time, and the contract auto-finalized the fraudulent transaction. | I7: https://lazarus.day/reports/a-detailed-post-mortem-on-the-afx-security-incident-P8mpR/ | J7: https://www.coindesk.com/tech/2026/07/23/arbitrum-based-afx-trade-drained-of-usd24-million-after-bridge-keys-compromised | K7: https://en.cryptonomist.ch/2026/07/31/afx-bridge-exploit-recovery/ | L7: E2 | M7: Credential Seizure (CS) | N7: FD-5 Governance & Operations | O7: The attacker obtained private keys for enough bridge validators to meet the withdrawal quorum, so the contract was simply following its own rules when it accepted signatures it had no way of knowing were stolen. Using a genuinely stolen signing credential to authorize a transaction, rather than exploiting any code flaw, is the Credential Seizure pattern, and for this we have mapped it to Credential Seizure (CS). Validator signing keys are part of the bridge's persistent operational control plane, so for this we have mapped it to FD-5 Governance & Operations. | Q7: None recorded | R7: No | U7: =IF(L7="E4","Low",IF(OR(R7="Yes",L7="E3"),"Medium","High")) -> High | X7: Bridge-held assets withdrawn
A8: BR-007 | B8: 46223 | C8: =YEAR(B8) -> 2026 | D8: Wanchain (Cardano ↔ BNB Chain bridge, NIGHT token) | E8: $9–13M | F8: 9000000 | G8: Reported range $9–13M; conservative lower bound used. | H8: A message-encoding ambiguity in the bridge's TreasuryCheck validator. The contract signed off on withdrawals by concatenating 14 different variable-length fields into one message with no separators or length markers — meaning two different amounts could produce byte sequences that looked identical to the signature check. The attacker took a legitimate MPC-signed authorization for a tiny withdrawal (~3,110 NIGHT) and shifted the byte boundary between two number fields so the same signature also validated a withdrawal over 65,000 times larger. | I8: https://medium.com/@wanchain_org/cardano-bnb-chain-bridge-incident-post-mortem-353e465276e7 | J8: https://blocksec.com/blog/web3-security-allbridge-wanchain-exploits | K8: https://www.cryptotimes.io/insights/wanchain-night-bridge-exploit-signature-flaw/ | L8: E1 | M8: Proof Forgery (PF) | N8: FD-3 Verification | O8: The flaw was in how the TreasuryCheck validator authenticated a signed withdrawal message. An encoding ambiguity let one genuine signature validate two very different amounts, meaning the signature check approved an unauthorized value. A flaw in the message authentication mechanism that lets an unauthorized value pass as valid is Proof Forgery, and for this we have mapped it to Proof Forgery (PF). TreasuryCheck is the component responsible for confirming a withdrawal request is authentic before it executes, so for this we have mapped it to FD-3 Verification. | Q8: None recorded | R8: No | U8: =IF(L8="E4","Low",IF(OR(R8="Yes",L8="E3"),"Medium","High")) -> High | X8: Bridge-held assets withdrawn
A9: BR-008 | B9: 46222 | C9: =YEAR(B9) -> 2026 | D9: Allbridge Core (Solana stablecoin pools) | E9: ~$1.65M | F9: 1650000 | G9: Reported as Jul 19–20, 2026; start date used. | H9: A flash-loan price manipulation attack on the bridge's internal liquidity accounting. The attacker flash-borrowed $1.12M in USDC, then ran a rapid sequence of same-asset stablecoin swaps specifically designed to break the pool's internal virtual-balance math, severely mispricing USDT relative to USDC. They then withdrew a hugely outsized amount of USDC for a tiny amount of USDT, repaid the flash loan, and bridged the profit to Ethereum. Notably, this was the second time Allbridge suffered nearly this exact class of flash-loan attack. | I9: https://outposts.io/article/allbridge-core-resumes-operations-after-dollar165m-security-2073cf35-cbcf-40c2-9d6b-de033aaf5528 | J9: https://blocksec.com/blog/web3-security-allbridge-wanchain-exploits | K9: https://www.coindesk.com/business/2026/07/20/cross-chain-protocol-allbridge-halts-after-usd1-65-million-flash-loan-exploit | L9: E2 | M9: Economic-State Manipulation (ESM) | N9: FD-4 Execution | O9: The attacker used borrowed capital within a single transaction to break the pool's internal virtual-balance math, mispricing USDT against USDC, and then extracted an outsized withdrawal before repaying the loan. The object being manipulated is the bridge's economic state, its pool balances and the internal pricing derived from them; the flash loan is only the capital source that made the manipulation affordable, not the vulnerability itself. Distorting the economic state a bridge relies on to price or authorize a release, and extracting value from that distortion, is the Economic-State Manipulation pattern, and for this we have mapped it to Economic-State Manipulation (ESM). The manipulated pricing logic lives inside the function that actually executes withdrawals against pool reserves, so for this we have mapped it to FD-4 Execution. | Q9: Flash loan | R9: No | U9: =IF(L9="E4","Low",IF(OR(R9="Yes",L9="E3"),"Medium","High")) -> High | X9: Bridge-held assets withdrawn
A10: BR-009 | B10: 46220 | C10: =YEAR(B10) -> 2026 | D10: Across Protocol (Solana relayer) | E10: ~$4.5M paid out of ~$41.7M attempted | F10: 4500000 | G10: Amount actually paid out; ~$41.7M attempted but not realised excluded. | H10: A bug in off-chain relayer software, not in any on-chain contract. Across's Solana relayer trusted any inner instruction addressed through a specific program authority as a genuine "deposit" event, without checking a required 8-byte Anchor "event discriminator" that distinguishes real events from lookalikes. The attacker deployed a wrapper program that called a harmless read-only function while smuggling in 1,627 completely fabricated deposit events — no real funds ever moved on Solana — and the relayer paid out real capital against 581 of these phantom deposits before the hole was patched roughly 5 hours later. | I10: https://github.com/across-protocol/sdk/commit/2e2f9d9d1f9efdd48866bd04e27efadedc548142 | J10: https://www.gate.com/news/detail/across-solana-relayer-lost-45m-in-forged-deposit-attack-on-july-17-22917844 | K10: https://www.panews.io/articles/019f973d-a5ad-763c-b84f-6759531a170e | L10: E1 | M10: Event Injection (EI) | N10: FD-2 Relay | O10: The relayer paid out against 1,627 completely fabricated deposit events from a rogue program, having skipped the discriminator check that would have proven those events came from the real deposit program. Fabricated events accepted as genuine bridge activity is the Event Injection pattern, and for this we have mapped it to Event Injection (EI). The bug lived specifically in the off-chain relayer's own event validation code, not in how the source contract emits deposit events, so for this we have mapped it to FD-2 Relay rather than FD-1 Deposit. | P10: Official artefact is the protocol's own fix commit (SDK repository) rather than a written post-mortem. | Q10: None recorded | R10: No | U10: =IF(L10="E4","Low",IF(OR(R10="Yes",L10="E3"),"Medium","High")) -> High | X10: Bridge-held assets withdrawn
A11: BR-010 | B11: 46218 | C11: =YEAR(B11) -> 2026 | D11: TeleSwap (Bitcoin bridge) | E11: ~$735K | F11: 735000 | H11: A SPV-based Bitcoin↔EVM bridge whose Bitcoin-side hot wallet was drained through unspecified suspicious outflows (root cause not publicly disclosed by the team even days later). Stolen BTC was swapped to ETH via Chainflip and laundered through Tornado Cash. | I11: https://indagolabs.eu/news/tracing-the-teleswap-exploit-deanonymizing-tornado-cash-outflows-with-our-tool-multichain-detective/ | J11: https://hacked.slowmist.io/?c=Bridge&page=1 | K11: https://www.panews.io/articles/019f7ff7-69eb-72dd-84c5-2fadae2a43e9 | L11: E4 | M11: Credential Seizure (CS) | N11: FD-5 Governance & Operations | O11: The loss pattern, a Bitcoin-side hot wallet drained through unexplained outflows, matches a private key or hot wallet compromise rather than a smart-contract bug, since no on-chain logic flaw has been identified or disclosed. Funds moving out through a compromised custody credential rather than an exploited contract function is the Credential Seizure pattern, and for this we have mapped it to Credential Seizure (CS). Hot-wallet key custody is an off-chain operational control asset, so for this we have mapped it to FD-5 Governance & Operations. | P11: Root cause not publicly disclosed; CS/FD-5 classification is inferred from on-chain outflow behaviour. Re-check if a post-mortem is published. | Q11: None recorded | R11: No | U11: =IF(L11="E4","Low",IF(OR(R11="Yes",L11="E3"),"Medium","High")) -> Low | X11: Bridge-held assets withdrawn
A12: BR-011 | B12: 46160 | C12: =YEAR(B12) -> 2026 | D12: Verus-Ethereum Bridge | E12: ~$11.4–11.58M | F12: 11400000 | G12: Reported range $11.4–11.58M; conservative lower bound used. | H12: A missing validation check in the bridge's import/export verification function (checkExportAndTransfers/submitImports), which confirmed a transfer hash existed but never verified the value was actually backed by locked assets on the Verus source chain. The attacker triggered unbacked Ethereum-side payouts with nothing collateralizing them on the source side | I12: https://www.halborn.com/blog/post/explained-the-verus-ethereum-bridge-hack-may-2026 | J12: https://cryptopotato.com/hacker-steals-over-11m-from-verus-ethereum-bridge/ | K12: https://web.archive.org/web/20260518134150/https://www.theblock.co/post/401571/verus-ethereum-bridge-exploit | L12: E2 | M12: Proof Forgery (PF) | N12: FD-3 Verification | O12: checkExportAndTransfers and submitImports confirmed a transfer hash existed but never verified the value was backed by locked assets on the source chain, so an unbacked claim passed verification. Passing an unbacked claim through the verification gate is Proof Forgery, and for this we have mapped it to Proof Forgery (PF). The missing check sits directly inside the bridge's import and export verification function, so for this we have mapped it to FD-3 Verification. | Q12: None recorded | R12: No | U12: =IF(L12="E4","Low",IF(OR(R12="Yes",L12="E3"),"Medium","High")) -> High | X12: Bridge-held assets withdrawn
A13: BR-012 | B13: 46157 | C13: =YEAR(B13) -> 2026 | D13: THORChain | E13: $10.7M | F13: 10700000 | H13: Not a smart-contract bug at all — a cryptographic attack on THORChain's threshold signature scheme (GG20/TSS), which is supposed to ensure no single validator ever holds a full vault private key. A newly-joined malicious validator registered a deliberately malformed cryptographic key (missing a soundness check THORChain's library should have enforced) and, over two days of normal signing activity, harvested leaked fragments of other validators' key shares until they could reconstruct the entire vault's private key and sign an unauthorized withdrawal directly. | I13: https://blog.thorchain.org/thorchain-exploit-report-1 | J13: https://www.quillaudits.com/blog/hack-analysis/thorchain-gg20-hack | K13: https://blog.thorchain.org/thorchain-exploit-report-2 | L13: E1 | M13: Credential Seizure (CS) | N13: FD-5 Governance & Operations | O13: However unusual the method, the end result was the same as a stolen key. The attacker reconstructed a validator vault's actual private key by harvesting leaked key-share fragments over two days, then used that genuine key to sign an unauthorized withdrawal directly. Signing with a real, if illegitimately obtained, private key is the Credential Seizure pattern, and for this we have mapped it to Credential Seizure (CS). A reconstructed signing key is still a signing credential, the persistent control-plane asset this domain covers, so for this we have mapped it to FD-5 Governance & Operations. | Q13: None recorded | R13: No | U13: =IF(L13="E4","Low",IF(OR(R13="Yes",L13="E3"),"Medium","High")) -> High | X13: Bridge-held assets withdrawn
A14: BR-013 | B14: 46139 | C14: =YEAR(B14) -> 2026 | D14: ZetaChain | E14: ~$334K (internal wallets only) | F14: 334000 | H14: Three chained weaknesses in ZetaChain's GatewayEVM cross-chain messaging contract: (1) the sending side allowed anyone to trigger arbitrary cross-chain calls with no access control, (2) the receiving side would execute almost any instruction including transferFrom, and (3) some wallets had granted the gateway unlimited token approvals that were never revoked. The attacker chained all three to drain internal team wallets (no user funds affected) across four chains. | I14: https://www.theblock.co/post/399315/zetachain-post-mortem | J14: https://blog.solidityscan.com/zetachain-gateway-hack-analysis/ | K14: https://www.cryptotimes.io/2026/04/29/how-a-perfect-storm-of-3-bugs-led-to-zetachains-333k-gatewayevm-exploit/ | L14: E2 | M14: Logic Exploitation (LE) | N14: FD-4 Execution | O14: The root cause is a chain of missing access-control and input-validation checks in the GatewayEVM contract's own code. The contract did exactly what it was coded to do, it just never should have allowed an arbitrary instruction like transferFrom to be triggered this way. A structural coding flaw exploited by using the contract exactly as designed is the Logic Exploitation pattern, and for this we have mapped it to Logic Exploitation (LE). The flaw is in the destination-side function that actually executes the incoming cross-chain instruction, so for this we have mapped it to FD-4 Execution. | Q14: None recorded | R14: No | U14: =IF(L14="E4","Low",IF(OR(R14="Yes",L14="E3"),"Medium","High")) -> High | X14: Wallet funds drained (approvals or redirection)
A15: BR-014 | B15: 46130 | C15: =YEAR(B15) -> 2026 | D15: Kelp DAO / LayerZero | E15: ~$292M drained + ~$236M recycled through lending protocols | F15: 292000000 | G15: Bridge drain only; ~$236M subsequently borrowed on lending protocols is downstream (non-bridge) impact and excluded. | H15: The largest 2026 incident. An attacker compromised the trust assumptions behind LayerZero's off-chain Decentralized Verifier Network (DVN) — via RPC-layer poisoning — to forge a cross-chain proof and mint 116,500 fake rsETH out of nothing. They then used that fake collateral across Aave, Compound, and Euler to borrow ~$236M in real assets before anyone could react, triggering a bad-debt crisis across multiple lending protocols and chains | I15: https://layerzero.network/publications/kelpdao-incident-report.pdf | J15: https://www.halborn.com/blog/post/explained-the-kelp-dao-hack-april-2026 | K15: https://www.chainalysis.com/blog/kelpdao-bridge-exploit-april-2026/ | L15: E1 | M15: Proof Forgery (PF) | N15: FD-3 Verification | O15: The attacker compromised LayerZero's off-chain DVN verification layer to forge a cryptographically valid-looking cross-chain proof and mint fake rsETH with no genuine deposit behind it. Forging a valid-looking proof to obtain an unbacked release is the textbook Proof Forgery pattern, and for this we have mapped it to Proof Forgery (PF). The DVN is the component whose entire job is to verify that a claimed cross-chain state transition really happened, so for this we have mapped it to FD-3 Verification. | P15: Exploited component is LayerZero DVN verification of the rsETH bridge route; lending-market contagion is out of scope. | Q15: RPC poisoning | R15: Yes | S15: Infrastructure Hijacking (IH) | T15: FD-5 Governance & Operations | U15: =IF(L15="E4","Low",IF(OR(R15="Yes",L15="E3"),"Medium","High")) -> Medium | X15: Value of unbacked minted assets
A16: BR-015 | B16: 46125 | C16: =YEAR(B16) -> 2026 | D16: Hyperbridge / Polkadot (DOT) | E16: $2.5 Million | F16: 2500000 | H16: Proof Verification Flaw: Attacker exploited proof verification logic to forge cross-chain messages and mint 1 billion DOT on Ethereum. | I16: https://blog.hyperbridge.network/april-13-post-mortem/ | J16: https://coinmarketcap.com/academy/article/hyperbridge-exploit-mints-1b-dot-tokens-in-attack-certik-reports | K16: https://anomly.rs/hyperbridge-forged-postrequest | L16: E1 | M16: Proof Forgery (PF) | N16: FD-3 Verification | O16: The attacker exploited the bridge's proof verification logic directly to forge cross-chain messages that let them mint 1 billion DOT with no genuine deposit on the source side. Exploiting the verification logic itself to forge a message is Proof Forgery, and for this we have mapped it to Proof Forgery (PF). The exploited function is the one responsible for confirming that a minting message is backed by a real cross-chain transfer, so for this we have mapped it to FD-3 Verification. | Q16: None recorded | R16: No | U16: =IF(L16="E4","Low",IF(OR(R16="Yes",L16="E3"),"Medium","High")) -> High | X16: Reported figure; basis not specified
A17: BR-016 | B17: 46094 | C17: =YEAR(B17) -> 2026 | D17: Messina Bridge (Opulous/OPUL) | E17: $47.5 Million | F17: 47500000 | H17: ~475 million OPUL drained. A signature-replay/multiplication flaw in the bridge's hop() function. Messina's Guardian network signs any valid on-chain event without checking business logic. The hop() function let an attacker take one legitimately-signed cross-chain approval (VAA) and repeatedly feed it back into hop() to mint a new legitimately-signed VAA for the same underlying deposit — over and over, multiplying one deposit into 143 valid claims. Each was cashed out on a different chain, draining escrow across Arbitrum, Ethereum, and BSC and collapsing the OPUL token to the point the project shut down entirely | I17: https://opulous.org/hack-report | L17: E3 | M17: Logic Exploitation (LE) | N17: FD-4 Execution | O17: The Guardians' signatures on each VAA were completely genuine. The bug was that hop() never marked a used VAA as spent, so the same real approval could be replayed to mint new valid claims 143 times over. A missing state-invalidation check exploited by reusing the contract's own logic as written is Logic Exploitation, and for this we have mapped it to Logic Exploitation (LE). The missing check lives in the function that executes each cross-chain hop or claim, not in the signature verification step itself, so for this we have mapped it to FD-4 Execution. | P17: Single official source (project hack report); satisfies the official post-mortem rule. | Q17: None recorded | R17: No | U17: =IF(L17="E4","Low",IF(OR(R17="Yes",L17="E3"),"Medium","High")) -> Medium | X17: Bridge-held assets withdrawn
A18: BR-017 | B18: 46074 | C18: =YEAR(B18) -> 2026 | D18: IoTeX (ioTube) | E18: $4.3 Million | F18: 4300000 | H18: Key Compromise: Unauthorized access to the private key managing the Validator contract on the Ethereum side. | I18: https://iotex.io/blog/security-incident-update-iotube-bridge-exploit-and-recovery-roadmap/ | L18: E3 | M18: Credential Seizure (CS) | N18: FD-5 Governance & Operations | O18: The attacker gained unauthorized access to the private key controlling the Ethereum-side Validator contract and used it directly to mint and move funds. Using a stolen private key to authorize the action is the Credential Seizure pattern, and for this we have mapped it to Credential Seizure (CS). That validator key is a persistent administrative credential, not a one-off transaction bug, so for this we have mapped it to FD-5 Governance & Operations. | P18: Single official source (project incident update); satisfies the official post-mortem rule. | Q18: None recorded | R18: No | U18: =IF(L18="E4","Low",IF(OR(R18="Yes",L18="E3"),"Medium","High")) -> Medium | X18: Reported figure; basis not specified
A19: BR-018 | B19: 46054 | C19: =YEAR(B19) -> 2026 | D19: CrossCurve | E19: $3 Million | F19: 3000000 | H19: Validation Flaw: Bugs in processing cross-chain messages from Axelar allowed forged messages to authorize fund releases without real deposits. A missing access-control check in a cross-chain messaging integration. CrossCurve's ReceiverAxelar contract inherited a function called expressExecute() from the Axelar SDK but never added the validation that normally confirms a message actually came through Axelar's Gateway. The only check left was "has this command ID been used before" — trivially bypassed by generating a fresh, unused ID. The attacker forged a cross-chain message claiming to be a legitimate unlock instruction and drained PortalV2 escrow contracts on both Ethereum and Arbitrum. | I19: https://crosscurve.medium.com/faq-user-questions-following-the-crosscurve-bridge-exploit-84c7dcc7a64b | J19: https://cantina.xyz/blog/crosscurve-bridge-hack-axelar-expressexecute | K19: https://www.halborn.com/blog/post/explained-the-crosscurve-hack-february-2026 | L19: E1 | M19: Proof Forgery (PF) | N19: FD-3 Verification | O19: The missing access-control check meant the destination contract would accept any freshly generated message as a legitimate Axelar-relayed instruction. The attacker forged an unlock message that was never actually verified against Axelar's Gateway. Forging a message that slips past a broken verification check is Proof Forgery, and for this we have mapped it to Proof Forgery (PF). The missing check sat directly inside the function responsible for validating that an incoming cross-chain message is authentic, so for this we have mapped it to FD-3 Verification. | Q19: None recorded | R19: No | U19: =IF(L19="E4","Low",IF(OR(R19="Yes",L19="E3"),"Medium","High")) -> High | X19: Bridge-held assets withdrawn
A20: BR-019 | B20: 46043 | C20: =YEAR(B20) -> 2026 | D20: Saga (SagaEVM) | E20: $7 Million | F20: 7000000 | H20: Message Spoofing: Attackers crafted custom IBC (Inter-Blockchain Communication) message payloads to bypass collateral verification in the ICS20 precompile bridge, minting Saga Dollar (DUSD) stablecoins with no real cross-chain collateral behind them. | I20: https://www.halborn.com/blog/post/explained-the-sagaevm-hack-january-2026 | J20: https://www.theblock.co/post/386638/sagaevm-suffers-exploit | L20: E2 | M20: Proof Forgery (PF) | N20: FD-3 Verification | O20: The attacker crafted a custom IBC message specifically to bypass the collateral verification check in the ICS20 precompile, letting the bridge accept a forged proof of backing that didn't exist. Crafting a message specifically to bypass a verification check is Proof Forgery, and for this we have mapped it to Proof Forgery (PF). The collateral check that was bypassed is the bridge's core verification gate for minting, so for this we have mapped it to FD-3 Verification. | P20: Second independent source (The Block) added to satisfy the evidence rule. | Q20: None recorded | R20: No | U20: =IF(L20="E4","Low",IF(OR(R20="Yes",L20="E3"),"Medium","High")) -> High | X20: Reported figure; basis not specified
A21: BR-020 | B21: 45957 | C21: =YEAR(B21) -> 2025 | D21: 402bridge | E21: $17,693 | F21: 17693 | H21: A leaked admin key stored insecurely on an internet-connected server. The x402 payment/bridge protocol needed an admin private key on its backend to process minting requests — and that key sat on a networked server rather than in cold/secure storage. Once leaked, an attacker transferred contract ownership to themselves and called an internal transferUserToken function to drain USDC from over 200 wallets that had granted the contract unlimited token approvals. | I21: https://www.cryptotimes.io/2025/10/28/402bridge-exploited-for-17k-in-private-key-leak-amid-x402-trend/ | J21: https://crypto.news/402bridge-hack-leads-to-over-200-users-drained-of-usdc/ | K21: https://www.bitget.com/news/detail/12560605057036 | L21: E2 | M21: Credential Seizure (CS) | N21: FD-5 Governance & Operations | O21: A leaked admin private key let the attacker transfer contract ownership to themselves and call a privileged internal function directly. No contract logic was tricked, the admin credential itself was stolen. A stolen administrative credential used to seize ownership and call privileged functions is Credential Seizure, and for this we have mapped it to Credential Seizure (CS). An admin key with ownership transfer rights is a core piece of the bridge's governance and operational control, so for this we have mapped it to FD-5 Governance & Operations. | Q21: None recorded | R21: No | U21: =IF(L21="E4","Low",IF(OR(R21="Yes",L21="E3"),"Medium","High")) -> High | X21: Wallet funds drained (approvals or redirection)
A22: BR-021 | B22: 45924 | C22: =YEAR(B22) -> 2025 | D22: GriffinAI (GAIN token, LayerZero bridge) | E22: ~$3 Million | F22: 3000000 | H22: An admin EOA compromise combined with a LayerZero peer-trust bypass. Less than 24 hours after GAIN's Binance Alpha launch, an attacker compromised an admin wallet on BNB Chain (likely via phishing) and called setPeer, designating a malicious Ethereum contract as a trusted LayerZero peer for the real GAIN OFT contract. The attacker deployed a fake token on Ethereum and "bridged" 5 billion of it through the now-poisoned peer connection — LayerZero's messaging faithfully relayed the mint instruction, and the legitimate BNB Chain GAIN contract minted 5 billion real GAIN tokens against nothing. The attacker sold ~2.8% on PancakeSwap for ~$3M before the token collapsed 90%; proceeds were laundered through deBridge and Tornado Cash. | I22: https://www.quillaudits.com/blog/hack-analysis/griffin-ai-exploit | J22: https://blog.verichains.io/p/deep-dive-into-the-gain-project-incident | K22: https://rekt.news/griffinai-rekt | L22: E2 | M22: Proof Forgery (PF) | N22: FD-3 Verification | O22: Once the admin wallet was compromised, the attacker's real move was to make a malicious contract a trusted LayerZero peer and then forge a bridge message from that fake peer, the same seize the verifier then forge the message pattern as The Sandbox. Forging a bridge message through a hijacked trust relationship to mint unbacked tokens is Proof Forgery, and for this we have mapped it to Proof Forgery (PF). Peer trust is exactly the mechanism LayerZero uses to verify that an incoming message is legitimate, so for this we have mapped it to FD-3 Verification. | Q22: Phishing (suspected) | R22: Yes | S22: Credential Seizure (CS) | T22: FD-5 Governance & Operations | U22: =IF(L22="E4","Low",IF(OR(R22="Yes",L22="E3"),"Medium","High")) -> Medium | X22: Real assets obtained with unbacked tokens
A23: BR-022 | B23: 45923 | C23: =YEAR(B23) -> 2025 | D23: Seedify SFUND Bridge | E23: $1.2 million | F23: 1200000 | H23: A compromised developer key on a bridge contract that should never have allowed unbacked minting. Attackers (linked to North Korea's Lazarus Group) obtained a Seedify developer's private key and used it to alter permissions on the LayerZero-based OFT bridge contract, minting large amounts of SFUND on Avalanche with nothing actually bridged from another chain, then dumped the fake tokens across Ethereum, Arbitrum, Base, and finally BNB Chain. | I23: https://decrypt.co/341076/north-korean-hackers-drain-1-2m-from-seedify-bridge | J23: https://crypto.news/seedifys-sfund-implodes-99-dprk-hackers-exploit-bridge-flaw/ | K23: https://games.gg/news/seedify-suffers-breach/ | L23: E2 | M23: Credential Seizure (CS) | N23: FD-5 Governance & Operations | O23: A compromised developer private key was used directly to alter bridge contract permissions and authorize unbacked minting. The credential, not the code, was the point of failure. A stolen developer credential used directly to authorize minting is Credential Seizure, and for this we have mapped it to Credential Seizure (CS). Developer and admin keys with permission altering power sit squarely in the governance and operations domain, so for this we have mapped it to FD-5 Governance & Operations. | Q23: None recorded | R23: No | U23: =IF(L23="E4","Low",IF(OR(R23="Yes",L23="E3"),"Medium","High")) -> High | X23: Real assets obtained with unbacked tokens
A24: BR-023 | B24: 45914 | C24: =YEAR(B24) -> 2025 | D24: Yala (Bitcoin-collateralized stablecoin bridge) | E24: ~$7.64 Million | F24: 7640000 | H24: A compromised temporary deployment key, not a smart-contract bug. An attacker obtained a temporary key meant for an authorized bridge deployment and used it to stand up an entirely unauthorized cross-chain bridge of their own. Through that rogue bridge, they overissued ~30 million YU tokens on Solana with nothing backing them, then drained ~7.64 million USDC (~1,636 ETH) through the withdrawal path — depegging YU to $0.20 before the team burned the illegitimate supply and injected $5.5M to restore the peg. Core protocol contracts and Bitcoin reserves were untouched; Bangkok police arrested the suspect on October 29, 2025. | I24: https://www.halborn.com/blog/post/explained-the-yala-hack-september-2025 | J24: https://www.bitget.com/news/detail/12560604970177 | K24: https://quadrigainitiative.com/casestudy/yalaprotocoldormantoftuunauthorizedmintandbridge.php | L24: E2 | M24: Credential Seizure (CS) | N24: FD-5 Governance & Operations | O24: A compromised temporary deployment key gave the attacker the same standing as an authorized deployer, letting them stand up and operate their own unauthorized bridge instance. A stolen deployment credential used to gain standing equivalent to an authorized operator is Credential Seizure, and for this we have mapped it to Credential Seizure (CS). Deployment and admin credentials are part of the bridge's operational control plane, so for this we have mapped it to FD-5 Governance & Operations. | Q24: None recorded | R24: No | U24: =IF(L24="E4","Low",IF(OR(R24="Yes",L24="E3"),"Medium","High")) -> High | X24: Bridge-held assets withdrawn
A25: BR-024 | B25: 45909 | C25: =YEAR(B25) -> 2025 | D25: Shibarium Bridge | E25: $2.4 Million | F25: 2400000 | H25: Signature Manipulation: Combined flash-loan and manipulated validator signatures to bypass proper collateralization. A flash-loan-powered validator takeover. Shibarium's bridge needed a two-thirds validator majority (8 of 12) to approve state checkpoints. The attacker flash-borrowed 4.6 million BONE tokens, delegated them to a compromised validator, and briefly pushed their controlled stake past the two-thirds threshold — enough to sign a fraudulent checkpoint and authorize a bogus bridge withdrawal of ETH and SHIB, all within a single block, repaying the flash loan with the stolen funds. | I25: https://news.shib.io/2025/09/22/shibarium-bridge-exploit-kaal-drops-latest-dev-report-post-hack/ | J25: https://www.theblock.co/post/370536/shibarium-bridge-suffers-sophisticated-flash-loan-attack-with-2-4-million-drained | K25: https://cryptonews.com/news/shibarium-reboots-after-4m-hack-pledges-user-refunds-heres-the-plan/ | L25: E1 | M25: Economic-State Manipulation (ESM) | N25: FD-4 Execution | O25: The attacker used flash-loaned BONE to temporarily inflate delegated stake past the two-thirds validator signing threshold within one block, pushed through a fraudulent checkpoint and withdrawal, and repaid the loan from the proceeds. The object being manipulated is the bridge's economic security state, the stake distribution that decides who may sign checkpoints; the flash loan only supplied the temporary capital. Distorting the economic state that a bridge's authorization depends on, and extracting value from that distortion, is the Economic-State Manipulation pattern, and for this we have mapped it to Economic-State Manipulation (ESM). The manipulated stake threshold directly gates the function that executes the withdrawal, so for this we have mapped it to FD-4 Execution. | Q25: Flash loan; compromised validator | R25: Yes | S25: Credential Seizure (CS) | T25: FD-5 Governance & Operations | U25: =IF(L25="E4","Low",IF(OR(R25="Yes",L25="E3"),"Medium","High")) -> Medium | X25: Bridge-held assets withdrawn
A26: BR-025 | B26: 45847 | C26: =YEAR(B26) -> 2025 | D26: ZKSwap Ethereum Bridge | E26: $5 million | F26: 5000000 | H26: A broken proof-verification function. ZKSwap's emergency "Exodus Mode" (meant to let users self-withdraw if operators go offline) relied on a verifyExitProof() function that always returned true instead of actually checking the cryptographic proof. The attacker submitted completely fabricated withdrawal proofs, which were accepted as genuine, then exploited weak duplicate-claim logic to repeat the trick across multiple token balances before withdrawing. | I26: https://www.blockaid.io/blog/how-zkswaps-5m-exploit-couldve-been-prevented-with-onchain-monitoring | J26: https://blog.verichains.io/p/audit-the-deployment-not-just-the | K26: https://quadrigainitiative.com/casestudy/zkswapexodusmodeflawenabledfakeproofwithdrawals.php | L26: E2 | M26: Proof Forgery (PF) | N26: FD-3 Verification | O26: verifyExitProof() was hardcoded to always return true instead of actually checking the submitted cryptographic proof, so completely fabricated withdrawal proofs passed verification. A proof-verification function that accepts fabricated proofs is the defining case of Proof Forgery, and for this we have mapped it to Proof Forgery (PF). verifyExitProof() is, by name and function, the bridge's proof verification checkpoint, so for this we have mapped it to FD-3 Verification. | Q26: None recorded | R26: No | U26: =IF(L26="E4","Low",IF(OR(R26="Yes",L26="E3"),"Medium","High")) -> High | X26: Bridge-held assets withdrawn
A27: BR-026 | B27: 45840 | C27: =YEAR(B27) -> 2025 | D27: Router Protocol | E27: $1.1 million | F27: 1100000 | H27: A logic flaw in Router Chain's custom cross-chain messaging module. The system failed to check that RequestSender == TxSender, letting the attacker spoof the sender field on an outbound request. The bridge's orchestrators unknowingly signed the forged request, and the Ethereum-side gateway contract released funds trusting that spoofed sender field. | I27: https://routerprotocol.medium.com/incident-report-router-protocol-asset-bridge-exploit-and-response-833f5bb95a31 | L27: E3 | M27: Logic Exploitation (LE) | N27: FD-2 Relay | O27: The bug is a missing equality check between RequestSender and TxSender in Router Chain's own messaging code, a straightforward coding omission that let a spoofed field slip through untouched logic. A plain missing-check coding defect, rather than a cryptographic or event-level forgery, is the Logic Exploitation pattern, and for this we have mapped it to Logic Exploitation (LE). The flaw sits inside the cross-chain messaging and orchestration module that relays and attests requests between chains, so for this we have mapped it to FD-2 Relay rather than FD-1 Deposit or FD-4 Execution. | P27: Single official source (project incident report); satisfies the official post-mortem rule. | Q27: None recorded | R27: No | U27: =IF(L27="E4","Low",IF(OR(R27="Yes",L27="E3"),"Medium","High")) -> Medium | X27: Bridge-held assets withdrawn
A28: BR-027 | B28: 45809 | C28: =YEAR(B28) -> 2025 | D28: Force Bridge | E28: $3.76 Million | F28: 3760000 | H28: Access Control: Compromised private keys allowed unauthorized access to critical token swap and withdrawal functions. A supply chain attack, not a smart contract bug. Attackers slipped malicious code into a Docker image deployed to validator nodes during an April system upgrade, which secretly exfiltrated validator private keys over encrypted channels. Weeks later, they used those stolen keys to push through fraudulent "unlock" transactions on Ethereum and BNB Chain, draining ETH, USDT, USDC, DAI, and WBTC | I28: https://talk.nervos.org/t/force-bridge-incident-root-cause-analysis-user-commitment/8801 | J28: https://thedefiant.io/news/hacks/nervos-networks-force-bridge-cross-chain-hack-exploits-access-control-steals-3-9-26adcaf3 | K28: https://talk.nervos.org/t/force-bridge-user-compensation-plan-announcement/8810 | L28: E1 | M28: Infrastructure Hijacking (IH) | N28: FD-5 Governance & Operations | O28: The attacker's entry point was the CI/CD deployment pipeline itself, malicious code was slipped into a Docker image pushed to validator nodes during a routine system upgrade, and that code exfiltrated validator private keys as a side effect. Compromising the software supply chain and build pipeline to inject malicious capability, rather than directly targeting an individual's key through phishing, is the Infrastructure Hijacking pattern, and for this we have mapped it to Infrastructure Hijacking (IH). CI/CD pipelines and deployment infrastructure are explicitly part of the supporting off-chain infrastructure this domain covers, so for this we have mapped it to FD-5 Governance & Operations. | Q28: Validator key exfiltration | R28: Yes | S28: Credential Seizure (CS) | T28: FD-5 Governance & Operations | U28: =IF(L28="E4","Low",IF(OR(R28="Yes",L28="E3"),"Medium","High")) -> Medium | X28: Bridge-held assets withdrawn
A29: BR-028 | B29: 45655 | C29: =YEAR(B29) -> 2024 | D29: FEG Token Bridge (SmartBridge) | E29: $1.3 Million | F29: 1300000 | H29: FEG's SmartBridge relies on Wormhole to carry cross-chain messages, and only its relayer contract is allowed to register a withdrawal in SmartBridge. That relayer maintains a whitelist of source addresses but lets the whitelist itself be updated via an incoming bridged message, and never checks whether the message doing the updating was actually authorized to do so. The attacker crafted a malicious Wormhole message on one chain that added their own contract to the whitelist, then sent a second message invoking registerWithdraw to credit themselves a withdrawable FEG balance with no matching deposit. The same three-step exploit was repeated across Ethereum, Base, and BSC for a combined ~$1.3M, and the proceeds were swapped to ETH/BNB and sent to Tornado Cash. | I29: https://www.certik.com/blog/feg-bridge-exploit-technical-analysis | J29: https://www.halborn.com/blog/post/explained-the-feed-every-gorilla-feg-hack-december-2024 | L29: E2 | M29: Event Injection (EI) | N29: FD-2 Relay | O29: The FEG Relayer contract received an incoming Wormhole message and registered a withdrawal without ever checking whether the message's source address was actually authorized to trigger that registration, so a malicious message from an unrelated address was processed as if it were a genuine bridge instruction. Accepting a message whose source was never validated as a real, authorized bridge action is the event source validation failure that defines Event Injection, and for this we have mapped it to Event Injection (EI). The missing check lived specifically inside the relayer contract's own message handling code, not in how deposits are emitted on the source chain, so for this we have mapped it to FD-2 Relay. | Q29: None recorded | R29: No | U29: =IF(L29="E4","Low",IF(OR(R29="Yes",L29="E3"),"Medium","High")) -> High | X29: Bridge-held assets withdrawn
A30: BR-029 | B30: 45510 | C30: =YEAR(B30) -> 2024 | D30: Ronin Bridge (2nd incident) | E30: $12 Million | F30: 12000000 | H30: Ronin's team upgraded its bridge manager from V2 to V4 and deployed a new MainchainGatewayV3 implementation, but never called the required initializeV3 function. That left the newly introduced _totalOperatorWeight storage variable at its zero default, which silently disabled the minimumVoteWeight check, the safeguard meant to confirm that enough validator weight had signed off before a withdrawal could execute. 48 minutes after the upgrade, an MEV bot spotted that any withdrawal request would now pass this check regardless of signer weight and withdrew 4,000 ETH and $2M USDC; a pre-existing daily withdrawal cap prevented a further ~$72M from being taken, and the funds were returned within hours. | I30: https://blog.solidityscan.com/ronin-bridge-hack-analysis-d8f64b8fe683/ | J30: https://www.beosin.com/resources/the-root-cause-of-ronin-bridges-abnormal-activities | L30: E2 | M30: Logic Exploitation (LE) | N30: FD-3 Verification | O30: The team's contract upgrade never called initializeV3, leaving the _totalOperatorWeight variable at its zero default, so the minimumVoteWeight check silently accepted any withdrawal regardless of how much validator weight actually signed it. The contract executed exactly as coded, it simply never enforced the safeguard it was supposed to, which is the Logic Exploitation pattern, and for this we have mapped it to Logic Exploitation (LE). The disabled minimumVoteWeight parameter is specifically the multi-signature consensus check that is meant to confirm sufficient validator weight approved a withdrawal before it is authorized, so for this we have mapped it to FD-3 Verification. | Q30: None recorded | R30: No | U30: =IF(L30="E4","Low",IF(OR(R30="Yes",L30="E3"),"Medium","High")) -> High | X30: Bridge-held assets withdrawn
A31: BR-030 | B31: 45489 | C31: =YEAR(B31) -> 2024 | D31: Li.Fi (bridge / DEX aggregator) | E31: ~$11.6 Million | F31: 11600000 | H31: Five days before the attack, LI.FI deployed a new GasZipFacet contract to enable gas refueling during bridging. Its depositToGasZipERC20 function passed a user-supplied _swapData argument straight into LibSwap.swap(), which executes a low-level call using whatever target address and call data it's given. Every other facet in LI.FI's Diamond contract checked that call target against a whitelist of approved DEXs and contracts before executing it, but GasZipFacet was missing that check. The attacker crafted a swapData payload that called transferFrom instead of a genuine swap, draining USDC, USDT, and DAI from any of the 153 wallets on Ethereum and Arbitrum that had granted the LI.FI contract an infinite approval. | I31: https://li.fi/knowledge-hub/incident-report-16th-july | J31: https://blocksec.com/blog/illicit-fund-flow-case-study-lifi-attack-metasleuth | L31: E1 | M31: Logic Exploitation (LE) | N31: FD-4 Execution | O31: The newly deployed GasZipFacet contract passed attacker-controlled call data straight into LibSwap.swap() without checking it against the whitelist of approved contracts and functions that every other facet enforced, letting the attacker substitute a transferFrom call for a swap. A missing whitelist check in the contract's own call-execution logic, rather than any forged message or stolen key, is the Logic Exploitation pattern, and for this we have mapped it to Logic Exploitation (LE). The unchecked call sits inside the function that actually executes the token movement against approved wallets, so for this we have mapped it to FD-4 Execution. | P31: Included: exploited GasZipFacet is the aggregator's cross-chain gas-refuel (bridging) facet. | Q31: None recorded | R31: No | U31: =IF(L31="E4","Low",IF(OR(R31="Yes",L31="E3"),"Medium","High")) -> High | X31: Wallet funds drained (approvals or redirection)
A32: BR-031 | B32: 45426 | C32: =YEAR(B32) -> 2024 | D32: ALEX Lab (XLink Bridge) | E32: $4.3 Million | F32: 4300000 | H32: CertiK traced the incident to a phishing attack that compromised the private key of ALEX's XLink bridge deployer account. Using that key, the attacker pushed several unauthorized proxy upgrades to the Bridge Endpoint contract on BNB Smart Chain and to the corresponding contract on the Stacks/Bitcoin side, redirecting the bridge's withdrawal logic to a malicious implementation they controlled. The attacker withdrew BTC, USDC, and Sugar Kingdom (SKO) tokens, and attempted a larger withdrawal on BNB Chain, but a bug in their own malicious implementation let a white-hat front-run and secure part of the funds; ALEX later recovered a large share of the total through a 10% bounty negotiation. | I32: https://cryptoslate.com/bitcoin-defi-app-alex-lab-links-4-million-exploit-to-lazarus-group/ | J32: https://www.certik.com/blog/alex | K32: https://www.coindesk.com/business/2024/05/15/bitcoin-defi-tool-alex-lab-loses-43m-in-hack-offers-10-bounty-for-stolen-funds | L32: E2 | M32: Credential Seizure (CS) | N32: FD-5 Governance & Operations | O32: A phishing attack compromised the deployer's private key, and the attacker used that key directly to push several unauthorized proxy upgrades to the Bridge Endpoint contract, redirecting withdrawals to themselves with no code vulnerability involved. Using a genuinely stolen credential to authorize the action directly is the Credential Seizure pattern, and for this we have mapped it to Credential Seizure (CS). A deployer key with upgrade authority over the bridge contract is a persistent administrative credential, so for this we have mapped it to FD-5 Governance & Operations. | Q32: Phishing | R32: No | U32: =IF(L32="E4","Low",IF(OR(R32="Yes",L32="E3"),"Medium","High")) -> High | X32: Bridge-held assets withdrawn
A33: BR-032 | B33: 45408 | C33: =YEAR(B33) -> 2024 | D33: Pike Finance (1st incident) | E33: ~$299K | F33: 299000 | H33: Pike integrated Circle's CCTP (via Gelato automation) to let users mint USDC directly on a destination chain after burning it on a source chain, but responsibility for validating the receiver address and transfer amount inside each incoming CCTP message was left to Pike's own contract rather than Circle's or Gelato's infrastructure. That validation was missing, so the attacker submitted a forged CCTP message with a manipulated recipient address and amount, which Pike's USDC pool accepted as a legitimate mint instruction and paid out against, draining ~$299K across Ethereum, Arbitrum, and Optimism. | I33: https://mirror.xyz/pikefinance.eth/klLV4rRqNYxjRQp0NAfVLboLYtX98P9iYOOf06FUapg | J33: https://www.certik.com/blog/pike-finance-incident-analysis | L33: E1 | M33: Proof Forgery (PF) | N33: FD-3 Verification | O33: Pike's own integration was responsible for validating the receiver address and amount inside an incoming CCTP cross-chain message before honoring it, and that validation was missing, so the attacker submitted a forged message with a manipulated recipient and amount that Pike accepted as a legitimate mint instruction. Forging a cross-chain message that passes an inadequate verification check to obtain a fraudulent release is the Proof Forgery pattern, and for this we have mapped it to Proof Forgery (PF). The missing validation sat directly inside the step responsible for confirming that an incoming CCTP message is authentic before funds move, so for this we have mapped it to FD-3 Verification. | P33: Included: exploited component is Pike's handling of incoming Circle CCTP cross-chain messages. | Q33: None recorded | R33: No | U33: =IF(L33="E4","Low",IF(OR(R33="Yes",L33="E3"),"Medium","High")) -> High | X33: Bridge-held assets withdrawn
A34: BR-033 | B34: 45406 | C34: =YEAR(B34) -> 2024 | D34: XBridge | E34: ~$1.6 Million | F34: 1600000 | H34: XBridge lets users register a token pair via listToken, which records the caller as that token's _tokenOwner and grants them the right to deposit and withdraw the underlying baseToken as a bridge liquidity provider. The function never checked whether a pair had already been registered by someone else before letting a new caller claim ownership of the same baseToken under a different corresponding token, so the attacker waited for a real liquidity provider to list and fund a pair, then re-called listToken to overwrite themselves in as the new _tokenOwner and called withdrawTokens to drain the liquidity that the original owner had deposited, across Ethereum and BNB Chain. | I34: https://www.cryptotimes.io/2024/04/24/saitachains-xbridge-experienced-a-security-breach/ | J34: https://blog.verichains.io/p/when-the-bridge-is-the-risk | K34: https://olympix.security/biweekly-exploits/6m-stolen-alexlab-ngfs-xbridge-and-yiedl-compromised-by-key-theft-and-broken-access-controls | L34: E2 | M34: Logic Exploitation (LE) | N34: FD-4 Execution | O34: The listToken function never verified that the caller matched the existing token owner, so the attacker simply re-registered themselves as the owner of a token pair that someone else had already funded, then called withdrawTokens to drain it without ever depositing anything. A missing ownership check in the contract's own registration and withdrawal logic, run exactly as written, is the Logic Exploitation pattern, and for this we have mapped it to Logic Exploitation (LE). The flaw sits in the function that actually releases funds to whoever holds the (falsely claimed) owner role, so for this we have mapped it to FD-4 Execution. | Q34: None recorded | R34: No | U34: =IF(L34="E4","Low",IF(OR(R34="Yes",L34="E3"),"Medium","High")) -> High | X34: Bridge-held assets withdrawn
A35: BR-034 | B35: 45307 | C35: =YEAR(B35) -> 2024 | D35: Socket.tech (Bungee Bridge) | E35: $3.3 Million | F35: 3300000 | H35: Three days before the attack, Socket deployed a new route inside its SocketGateway contract. The route's performAction function had incomplete validation of its input parameters, and the attacker used that gap to invoke transfers directly against the token allowances that users had previously granted to SocketGateway, without those users signing any new transaction. 232 wallets that had left infinite approvals in place lost a combined $3.3M across USDC and several other assets before the route was disabled; Socket later recovered ~$2.3M through negotiation and covered the remaining shortfall. | I35: https://www.certik.com/blog/socket-tech-incident-analysis | J35: https://thedefiant.io/news/defi/socket-resumes-operations-after-users-lost-usd3-3m-to-exploit | L35: E2 | M35: Logic Exploitation (LE) | N35: FD-4 Execution | O35: A newly deployed route's performAction function had incomplete input validation, and the attacker used that gap to invoke transfers directly against any wallet that had granted the SocketGateway contract an unlimited token approval, with no forged message or stolen key involved. A missing input-validation check in the contract's own action-execution logic is the Logic Exploitation pattern, and for this we have mapped it to Logic Exploitation (LE). The vulnerable function is the one that actually executes the token transfer against a user's standing approval, so for this we have mapped it to FD-4 Execution. | P35: Included: exploited route sits in SocketGateway, the bridge aggregator's cross-chain routing contract. | Q35: None recorded | R35: No | U35: =IF(L35="E4","Low",IF(OR(R35="Yes",L35="E3"),"Medium","High")) -> High | X35: Wallet funds drained (approvals or redirection)
